<?xml version="1.0" ?>
<robot name="myrobot" xmlns:xacro="http://www.ros.org/wiki/xacro">

<xacro:include filename="$(find myrobot_description)/urdf/materials.xacro" />
<xacro:include filename="$(find myrobot_description)/urdf/myrobot.trans" />
<xacro:include filename="$(find myrobot_description)/urdf/myrobot.gazebo" />
<link name="base_link">
  <inertial>
    <origin rpy="0 0 0" xyz="0.0038679374402001226 3.5649192997169336e-05 0.052918293473761"/>
    <mass value="2.3138752403503777"/>
    <inertia ixx="0.007906" ixy="-4e-06" ixz="-0.000337" iyy="0.008384" iyz="-3e-06" izz="0.014779"/>
  </inertial>
  <visual>
    <origin rpy="0 0 0" xyz="0 0 0"/>
    <geometry>
      <mesh filename="package://myrobot_description/meshes/base_link.stl" scale="0.001 0.001 0.001"/>
    </geometry>
    <material name="silver"/>
  </visual>
  <collision>
    <origin rpy="0 0 0" xyz="0 0 0"/>
    <geometry>
      <mesh filename="package://myrobot_description/meshes/base_link.stl" scale="0.001 0.001 0.001"/>
    </geometry>
  </collision>
</link>

<link name="rightwheel_1">
  <inertial>
    <origin rpy="0 0 0" xyz="-1.1580046200244058e-17 -0.012499999999999997 0.0"/>
    <mass value="0.1826050729899067"/>
    <inertia ixx="0.000124" ixy="-0.0" ixz="0.0" iyy="0.000228" iyz="0.0" izz="0.000124"/>
  </inertial>
  <visual>
    <origin rpy="0 0 0" xyz="-0.0 0.1 -0.05"/>
    <geometry>
      <mesh filename="package://myrobot_description/meshes/rightwheel_1.stl" scale="0.001 0.001 0.001"/>
    </geometry>
    <material name="silver"/>
  </visual>
  <collision>
    <origin rpy="0 0 0" xyz="-0.0 0.1 -0.05"/>
    <geometry>
      <mesh filename="package://myrobot_description/meshes/rightwheel_1.stl" scale="0.001 0.001 0.001"/>
    </geometry>
  </collision>
</link>

<link name="leftwheel_1">
  <inertial>
    <origin rpy="0 0 0" xyz="-1.1580046200244058e-17 0.012499999999999997 0.0"/>
    <mass value="0.1826050729899067"/>
    <inertia ixx="0.000124" ixy="-0.0" ixz="0.0" iyy="0.000228" iyz="-0.0" izz="0.000124"/>
  </inertial>
  <visual>
    <origin rpy="0 0 0" xyz="-0.0 -0.1 -0.05"/>
    <geometry>
      <mesh filename="package://myrobot_description/meshes/leftwheel_1.stl" scale="0.001 0.001 0.001"/>
    </geometry>
    <material name="silver"/>
  </visual>
  <collision>
    <origin rpy="0 0 0" xyz="-0.0 -0.1 -0.05"/>
    <geometry>
      <mesh filename="package://myrobot_description/meshes/leftwheel_1.stl" scale="0.001 0.001 0.001"/>
    </geometry>
  </collision>
</link>

<link name="lidar_1">
  <inertial>
    <origin rpy="0 0 0" xyz="-3.7375411832824e-07 -3.16808793696013e-07 0.012499999999999997"/>
    <mass value="0.10789485809488783"/>
    <inertia ixx="4.1e-05" ixy="-0.0" ixz="-0.0" iyy="4.1e-05" iyz="-0.0" izz="7e-05"/>
  </inertial>
  <visual>
    <origin rpy="0 0 0" xyz="-0.049876 -0.00046 -0.11"/>
    <geometry>
      <mesh filename="package://myrobot_description/meshes/lidar_1.stl" scale="0.001 0.001 0.001"/>
    </geometry>
    <material name="silver"/>
  </visual>
  <collision>
    <origin rpy="0 0 0" xyz="-0.049876 -0.00046 -0.11"/>
    <geometry>
      <mesh filename="package://myrobot_description/meshes/lidar_1.stl" scale="0.001 0.001 0.001"/>
    </geometry>
  </collision>
</link>

<joint name="Rev1" type="continuous">
  <origin rpy="0 0 0" xyz="0.0 -0.1 0.05"/>
  <parent link="base_link"/>
  <child link="rightwheel_1"/>
  <axis xyz="0.0 1.0 0.0"/>
</joint>

<joint name="Rev2" type="continuous">
  <origin rpy="0 0 0" xyz="0.0 0.1 0.05"/>
  <parent link="base_link"/>
  <child link="leftwheel_1"/>
  <axis xyz="0.0 1.0 0.0"/>
</joint>

<joint name="Rigid3" type="fixed">
  <origin rpy="0 0 0" xyz="0.049876 0.00046 0.11"/>
  <parent link="base_link"/>
  <child link="lidar_1"/>
</joint>

</robot>
